<?xml version="1.0" encoding="utf-8"?>
<!-- This URDF was automatically created by SolidWorks to URDF Exporter! Originally created by Stephen Brawner (brawner@gmail.com) 
     Commit Version: 1.6.0-4-g7f85cfe  Build Version: 1.6.7995.38578
     For more information, please see http://wiki.ros.org/sw_urdf_exporter -->
<robot name="robot_kin">
  <link name="base_link">
    <inertial>
      <origin xyz="-0.0514950390834328 0.00372680362943543 -0.0212713777766178" rpy="0 0 0" />
      <mass value="5.546524151294" />
      <inertia ixx="0.0390256274086559" ixy="7.53990510164341E-17" ixz="-9.49819895659914E-18" iyy="0.0390256274084877" iyz="-4.52445032425781E-14" izz="0.0727431794136434" />
    </inertial>
    <visual>
      <origin xyz="0 0 0" rpy="0 0 0" />
      <geometry>
        <mesh filename="package://robot_kin/meshes/base_link.STL" />
      </geometry>
      <material name="">
        <color rgba="0.647058823529412 0.619607843137255 0.588235294117647 1" />
      </material>
    </visual>
    <collision>
      <origin xyz="0 0 0" rpy="0 0 0" />
      <geometry>
        <mesh filename="package://robot_kin/meshes/base_link.STL" />
      </geometry>
    </collision>
  </link>
  <link name="omni_1">
    <inertial>
      <origin xyz="2.10248485288389E-15 -4.64905891561784E-16 -0.0150000000000003" rpy="0 0 0" />
      <mass value="0.208733977688544" />
      <inertia ixx="5.75297014634535E-05" ixy="-3.89635155736978E-20" ixz="5.02608940799584E-19" iyy="5.75297014634539E-05" iyz="-1.7427007015891E-19" izz="9.13704714530288E-05" />
    </inertial>
    <visual>
      <origin xyz="0 0 0" rpy="0 0 0" />
      <geometry>
        <mesh filename="package://robot_kin/meshes/omni_1.STL" />
      </geometry>
      <material name="">
        <color rgba="0.752941176470588 0.752941176470588 0.752941176470588 1" />
      </material>
    </visual>
    <collision>
      <origin xyz="0 0 0" rpy="0 0 0" />
      <geometry>
        <mesh filename="package://robot_kin/meshes/omni_1.STL" />
      </geometry>
    </collision>
  </link>
  <joint name="joint_omni_1" type="continuous">
    <origin xyz="-0.136496944367027 -0.143500815062323 -0.0472051656727379" rpy="-1.57079632679489 -1.18691023115661 2.61799387799149" />
    <parent link="base_link" />
    <child link="omni_1" />
    <axis xyz="0 0 1" />
    <dynamics damping="0.1" friction="0.1" />
  </joint>
  <link name="omni_2">
    <inertial>
      <origin xyz="2.51881848711832E-15 -2.0122792321331E-16 -0.0150000000000004" rpy="0 0 0" />
      <mass value="0.208733977688543" />
      <inertia ixx="5.75297014634536E-05" ixy="1.35525271560688E-20" ixz="5.37279608401087E-19" iyy="5.75297014634537E-05" iyz="-3.87797460613561E-19" izz="9.13704714530288E-05" />
    </inertial>
    <visual>
      <origin xyz="0 0 0" rpy="0 0 0" />
      <geometry>
        <mesh filename="package://robot_kin/meshes/omni_2.STL" />
      </geometry>
      <material name="">
        <color rgba="0.752941176470588 0.752941176470588 0.752941176470588 1" />
      </material>
    </visual>
    <collision>
      <origin xyz="0 0 0" rpy="0 0 0" />
      <geometry>
        <mesh filename="package://robot_kin/meshes/omni_2.STL" />
      </geometry>
    </collision>
  </link>
  <joint name="joint_omni_2" type="continuous">
    <origin xyz="-0.136496944367024 0.150954422321192 -0.0472051656727389" rpy="-1.5707963267949 0.532099877009558 0.523598775598294" />
    <parent link="base_link" />
    <child link="omni_2" />
    <axis xyz="0 0 1" />
    <dynamics damping="0.1" friction="0.1" />
  </joint>
  <link name="omni_3">
    <inertial>
      <origin xyz="2.04697370165263E-15 -4.57966997657877E-16 -0.0150000000000004" rpy="0 0 0" />
      <mass value="0.208733977688544" />
      <inertia ixx="5.75297014634535E-05" ixy="-5.59041745187838E-20" ixz="5.01350143462744E-19" iyy="5.75297014634538E-05" iyz="-2.67520268147213E-19" izz="9.13704714530288E-05" />
    </inertial>
    <visual>
      <origin xyz="0 0 0" rpy="0 0 0" />
      <geometry>
        <mesh filename="package://robot_kin/meshes/omni_3.STL" />
      </geometry>
      <material name="">
        <color rgba="0.752941176470588 0.752941176470588 0.752941176470588 1" />
      </material>
    </visual>
    <collision>
      <origin xyz="0 0 0" rpy="0 0 0" />
      <geometry>
        <mesh filename="package://robot_kin/meshes/omni_3.STL" />
      </geometry>
    </collision>
  </link>
  <joint name="joint_omni_3" type="continuous">
    <origin xyz="0.118508771484474 0.00372680362943003 -0.0472051656727379" rpy="-1.5707963267949 0.854297069502276 -1.57079632679491" />
    <parent link="base_link" />
    <child link="omni_3" />
    <axis xyz="0 0 1" />
    <dynamics damping="0.1" friction="0.1" />
  </joint>
  <link name="link_1">
    <inertial>
      <origin xyz="-0.00197622872489094 -4.49272203594166E-05 0.00633251365290859" rpy="0 0 0" />
      <mass value="0.214783356206923" />
      <inertia ixx="0.000365790344438595" ixy="1.90730142866856E-08" ixz="1.46206270755554E-05" iyy="0.000380010525298812" iyz="8.07220952141231E-07" izz="0.000475014888435784" />
    </inertial>
    <visual>
      <origin xyz="0 0 0" rpy="0 0 0" />
      <geometry>
        <mesh filename="package://robot_kin/meshes/link_1.STL" />
      </geometry>
      <material name="">
        <color rgba="0.498039215686275 0.498039215686275 0.498039215686275 1" />
      </material>
    </visual>
    <collision>
      <origin xyz="0 0 0" rpy="0 0 0" />
      <geometry>
        <mesh filename="package://robot_kin/meshes/link_1.STL" />
      </geometry>
    </collision>
  </link>
  <joint name="joint_link_1" type="fixed">
    <origin xyz="-0.0514950390831942 0.00372680362943392 0.0242948343272624" rpy="0 0 0" />
    <parent link="base_link" />
    <child link="link_1" />
    <axis xyz="0 0 0" />
  </joint>
  <link name="link_2">
    <inertial>
      <origin xyz="0.0734879371385836 -0.00334262643425878 0.00783116598654759" rpy="0 0 0" />
      <mass value="0.108863827343016" />
      <inertia ixx="1.52983726752256E-05" ixy="3.25169315859978E-06" ixz="2.96831173668244E-06" iyy="0.000349212764999917" iyz="-1.20507616431351E-07" izz="0.000359580214053703" />
    </inertial>
    <visual>
      <origin xyz="0 0 0" rpy="0 0 0" />
      <geometry>
        <mesh filename="package://robot_kin/meshes/link_2.STL" />
      </geometry>
      <material name="">
        <color rgba="0.498039215686275 0.498039215686275 0.498039215686275 1" />
      </material>
    </visual>
    <collision>
      <origin xyz="0 0 0" rpy="0 0 0" />
      <geometry>
        <mesh filename="package://robot_kin/meshes/link_2.STL" />
      </geometry>
    </collision>
  </link>
  <joint name="joint_link_2" type="revolute">
    <origin xyz="0 0.005 0.09" rpy="1.5708 -0.97083 3.1416" />
    <parent link="link_1" />
    <child link="link_2" />
    <axis xyz="0 0 1" />
    <limit lower="0" upper="0" effort="0" velocity="0" />
    <dynamics damping="0.1" friction="0.1" />
  </joint>
  <link name="link_3">
    <inertial>
      <origin xyz="0.0679394800286911 -0.00254732956132153 0.00791117403147978" rpy="0 0 0" />
      <mass value="0.0922267153628876" />
      <inertia ixx="1.11543901229101E-05" ixy="3.03180485829024E-06" ixz="2.56993305226668E-06" iyy="0.00031313631090358" iyz="-1.19027339136059E-07" izz="0.000318250360418558" />
    </inertial>
    <visual>
      <origin xyz="0 0 0" rpy="0 0 0" />
      <geometry>
        <mesh filename="package://robot_kin/meshes/link_3.STL" />
      </geometry>
      <material name="">
        <color rgba="0.498039215686275 0.498039215686275 0.498039215686275 1" />
      </material>
    </visual>
    <collision>
      <origin xyz="0 0 0" rpy="0 0 0" />
      <geometry>
        <mesh filename="package://robot_kin/meshes/link_3.STL" />
      </geometry>
    </collision>
  </link>
  <joint name="joint_link_3" type="revolute">
    <origin xyz="0.17 0 0.015" rpy="0 0 -1.2916" />
    <parent link="link_2" />
    <child link="link_3" />
    <axis xyz="0 0 1" />
    <limit lower="0" upper="0" effort="0" velocity="0" />
    <dynamics damping="0.1" friction="0.1" />
  </joint>



  <!-- Camera Link -->
  <link name="camera_link">
    <inertial>
      <origin xyz="0 0 0" rpy="0 0 0"/>
      <mass value="0.1"/>
      <inertia ixx="0.001" ixy="0" ixz="0" iyy="0.001" iyz="0" izz="0.001"/>
    </inertial>
    <visual>
      <origin xyz="0 0 0" rpy="0 0 0"/>
      <geometry>
        <box size="0.01 0.01 0.01" />
      </geometry>
      <material name="Blue">
        <color rgba="0 0 1 1"/>
      </material>
    </visual>
    <collision>
      <origin xyz="0 0 0" rpy="0 0 0"/>
      <geometry>
        <box size="0.05 0.05 0.05"/>
      </geometry>
    </collision>
  </link>

  <!-- Fixed Joint to attach Camera to Link 3 -->
  <joint name="camera_joint" type="fixed">
    <origin xyz="0 0 0.05" rpy="0 0 0"/>
    <parent link="link_3"/>
    <child link="camera_link"/>
  </joint>

  <!-- Gazebo Camera Sensor -->
  <gazebo reference="camera_link">
    <sensor type="camera" name="camera_sensor">
      <always_on>true</always_on>
      <update_rate>30</update_rate>
      <camera>
        <horizontal_fov>1.3962634</horizontal_fov>
        <image>
          <width>640</width>
          <height>480</height>
          <format>R8G8B8</format>
        </image>
        <clip>
          <near>0.1</near>
          <far>100</far>
        </clip>
      </camera>
      <plugin name="gazebo_ros_camera_controller" filename="libgazebo_ros_camera.so">
        <robotNamespace>/robot_kin</robotNamespace>
        <cameraName>camera</cameraName>
        <imageTopicName>image_raw</imageTopicName>
        <cameraInfoTopicName>camera_info</cameraInfoTopicName>
        <frameName>camera_link</frameName>
        <updateRate>30</updateRate>
      </plugin>
    </sensor>
  </gazebo>


  <!-- IMU Sensor Link
  <link name="imu_link">
    <inertial>
      <origin xyz="0 0 0" rpy="0 0 0"/>
      <mass value="0.01"/>
      <inertia ixx="0.001" ixy="0" ixz="0" iyy="0.001" iyz="0" izz="0.001"/>
    </inertial>
    <visual>
      <origin xyz="0 0 0" rpy="0 0 0"/>
      <geometry>
        <box size="0.02 0.02 0.02"/>
      </geometry>
      <material name="Green">
        <color rgba="0 1 0 1"/>
      </material>
    </visual>
    <collision>
      <origin xyz="0 0 0" rpy="0 0 0"/>
      <geometry>
        <box size="0.02 0.02 0.02"/>
      </geometry>
    </collision>
  </link>

  Fixed Joint to attach IMU to base_link (hoặc thay bằng link phù hợp)
  <joint name="imu_joint" type="fixed">
    <origin xyz="0 0 0.1" rpy="0 0 0"/>
    <parent link="base_link"/>
    <child link="imu_link"/>
  </joint>

  Gazebo IMU Sensor
  <gazebo reference="imu_link">
    <sensor type="imu" name="imu_sensor">
      <always_on>true</always_on>
      <update_rate>100</update_rate>
      <imu>
        <topic>imu/data</topic>
        <gaussian_noise>
          <mean>0.0</mean>
          <stddev>0.02</stddev>
        </gaussian_noise>
      </imu>
      <plugin name="gazebo_ros_imu_controller" filename="libgazebo_ros_imu.so">
        <robotNamespace>/robot_kin</robotNamespace>
        <bodyName>imu_link</bodyName>
        <topicName>imu/data</topicName>
        <frameName>imu_link</frameName>
      </plugin>
    </sensor>
  </gazebo> -->

</robot>